Workbook

Sheet Учёт
A1: № | B1: Пачка | C1: Дизайнер | D1: Email | E1: Телефон | F1: Город | G1: Тема письма (зацепка) | H1: Вариант | I1: Отправлено | J1: Ответ: дата | K1: Ответ: тип | L1: Наш ответ / follow-up: дата | M1: Статус диалога | N1: Заметки
A2: 1 | B2: campaign1 | C2: Ксения Разинкина | D2: razinkina_kseniya@mail.ru | F2: г. Москва | G2: Про «Студия 24 кв. м.» | H2: A | I2: 07.07.2026
A3: 2 | B3: campaign1 | C3: Анна и Дмитрий Коробко | D3: d.a.interiordesign@mail.ru | F3: г Москва | G3: Про «Квартира для молодой семьи 60м.кв.» | H3: B | I3: 07.07.2026
A4: 3 | B4: campaign1 | C4: Дизайн-студия «RiDiS PrO» | D4: studio.ridis@yandex.ru | E4: 79939645908 | F4: г Москва | G4: Про «Гостевой дом в Сочи с дизайном класса люкс» | H4: A | I4: 07.07.2026
A5: 4 | B5: campaign1 | C5: КубКвадрат студия | D5: info@kubkvadrat.ru | E5: 79057115735 | F5: г Москва | G5: Про «Не белый» | H5: B | I5: 07.07.2026
A6: 5 | B6: campaign1 | C6: Александр Липатов | D6: Lh-studio@mail.ru | F6: г Москва | G6: Про «Спальный отсек для близнецов - первооткрывателей дальнего космоса» | H6: A | I6: 07.07.2026 | K6: положительный | M6: диалог | N6: Попросил развёрнутую информацию. Отправлен полный follow-up: материалы, схема работы, презентация v2.
A7: 6 | B7: campaign1 | C7: Полина Уютная | D7: polina_u_1999@mail.ru | F7: г Москва | G7: Про ваш профиль на Флатике | H7: review | I7: 08.07.2026
A8: 7 | B8: campaign1 | C8: Ксения Попова | D8: hello@ksyuschenka.com | E8: 79523558208 | F8: г Москва | G8: Про «Кухня-гостиная в ЖК «Резиденции Сколково»» | H8: B | I8: 08.07.2026
A9: 8 | B9: campaign1 | C9: Евгения Заварзина | D9: zavarzina.evgeniya@yandex.ru | F9: г Москва | G9: Про ваш профиль на Флатике | H9: review | I9: 08.07.2026
A10: 9 | B10: campaign1 | C10: Yurov Interiors | D10: yurov-interiors@mail.ru | E10: 79034356354 | F10: г. Москва | G10: Про «River Sky» | H10: B | I10: 08.07.2026
A11: 10 | B11: campaign2 | C11: Любовь Крыгина | D11: l_krygina_design@mail.ru | F11: г. Москва | G11: Про «Летний сад, 4х комнатная квартира» | H11: A | I11: 08.07.2026
A12: 11 | B12: campaign2 | C12: Ксения Петрова | D12: PEtrovaKS1983@yandex.ru | F12: г Москва | G12: Про «Современная классика с элементами арт-деко» | H12: B | I12: 08.07.2026 | K12: отказ | M12: закрыто | N12: «Есть постоянный партнёр по мебели». Отправлен короткий необязывающий ответ, остаёмся на связи.
A13: 12 | B13: campaign2 | C13: Екатерина Пимкина | D13: pimkinak@bk.ru | F13: г. Москва | G13: Про «Дом на Новой Риге» | H13: A | I13: 08.07.2026
A14: 13 | B14: campaign2 | C14: Ольга Петрова | D14: olia.i.petrova@gmail.com | E14: 9197772519 | F14: г Москва | G14: Про «Мечты о море Франции» | H14: B | I14: 08.07.2026
A15: 14 | B15: campaign2 | C15: Olga Karpova | D15: h.d.studio@mail.ru | F15: г. Москва | G15: Про «Детский центр в Кемпински Гранд Отель Геленджик» | H15: A | I15: 08.07.2026 | N15: Письмо ушло дважды 08.07 (ручные тестовые запуски до файловой блокировки).
A16: 15 | B16: campaign2 | C16: Александра Гартке | D16: aleksandra.gartke@mail.ru | E16: 79690346046 | F16: г. Москва | G16: Про «Квартира в ЖК Сердце Столицы» | H16: B | I16: 09.07.2026
A17: 16 | B17: campaign2 | C17: Светлана Люзина | D17: lyuzina.lyuzina@yandex.ru | F17: г. Москва | G17: Про «Коттедж в посёлке «Павлово»» | H17: A | I17: 09.07.2026
A18: 17 | B18: campaign2 | C18: Наталья Балашова | D18: natalyarch@yandex.ru | E18: 9645051262 | F18: г Москва | G18: Про «ЖК Onyx Deluxe» | H18: B | I18: 09.07.2026
A19: 18 | B19: campaign2 | C19: Игорь Самойлов | D19: archijam@yandex.ru | E19: 79053349990 | F19: г Москва | G19: Про ваш профиль на Флатике | H19: A | I19: 09.07.2026
A20: 19 | B20: campaign2 | C20: УММ5 | Студия современного интерьера | D20: umm2005@mail.ru | E20: 79814643931 | F20: г Москва | G20: Про «Квартира 103м² в ЖК Famous, г. Москва» | H20: B | I20: 09.07.2026
A21: 20 | B21: campaign2 | C21: Студия дизайна и ремонта Katushhha | D21: logvinova-7777@mail.ru | E21: 79967896686 | F21: г. Россия | G21: Про «Дом французская классика» | H21: A | I21: 09.07.2026
A22: 21 | B22: campaign2 | C22: Ирина Бирюкова | D22: limartgroup@mail.ru | E22: 79257555068 | F22: г. Москва | G22: Про «Усадьба Шарапово» | H22: B | I22: 09.07.2026 | K22: деловой запрос | L22: 13.07.2026 | M22: расчёт изделия | N22: «Скиньте работы, стоимость, сроки и условия». 13.07 отправлен ответ по 4 пунктам + презентация v2, предложен расчёт изделия из её проекта.
A23: 22 | B23: campaign2 | C23: Алиса Баронова | D23: baronovaalisa@gmail.com | E23: 79185031519 | F23: г Москва | G23: Про «Роза пустыни» | H23: A | I23: 09.07.2026
A24: 23 | B24: campaign2 | C24: Сузанна Тасалиева | D24: susanna0939@yandex.ru | E24: 79210091675 | F24: г Калининград | G24: Про «Дом в Черняховске» | H24: B | I24: 09.07.2026
A25: 24 | B25: campaign2 | C25: Виктория Ретинская | D25: retinskaya.vika@gmail.com | E25: 79181575449 | F25: г Москва | G25: Про «ЖК Граф Толстой» | H25: A | I25: 09.07.2026
A26: 25 | B26: campaign3 | C26: Татьяна Алякова | D26: tna@alta-design.ru | F26: г. Москва | G26: Про «Домик беседующих стихий» | H26: B | I26: 10.07.2026
A27: 26 | B27: campaign3 | C27: SIMPLE HOME | D27: simple.home.m@yandex.ru | F27: г Москва | G27: Про «Проект ЖК Триумф Палас» | H27: A | I27: 10.07.2026
A28: 27 | B28: campaign3 | C28: Алёна Чекалина | D28: info@des-ign.ru | E28: 79166502951 | F28: г Москва | G28: Про «Модная панелька» | H28: B | I28: 10.07.2026
A29: 28 | B29: campaign3 | C29: Студия интерьера BACARDI | D29: panknat@list.ru | E29: 79165521215 | F29: г Москва | G29: Про «Реализованный проект ЖК Фридом» | H29: A | I29: 10.07.2026
A30: 29 | B30: campaign3 | C30: Виктория Власова | D30: info@victoriavlasova.ru | E30: 79037980940 | F30: г. Москва | G30: Про «Квартира в сталинском доме на Фрунзенской» | H30: B | I30: 10.07.2026
A31: 30 | B31: campaign3 | C31: Марина Терновая | D31: tma704@yandex.ru | E31: 9060502502 | F31: г. Москва | G31: Про «ЖК 2119» | H31: A | I31: 10.07.2026
A32: 31 | B32: campaign3 | C32: мастерская VVERHDNOM | D32: info@vverhdnom.com | E32: 79162989393 | F32: г Москва | G32: Про "Королев, ЖК "Театральный Парк" | H32: A | I32: 10.07.2026
A33: 32 | B33: campaign3 | C33: Ольга Задорожная | D33: olgaglushko25@gmail.com | E33: 9162403584 | F33: г. Москва | G33: Про «ЖК Башни Токио 50м2» | H33: B | I33: 10.07.2026
A34: 33 | B34: campaign3 | C34: Полина Епифанова | D34: pillar79@gmail.com | F34: г. Москва | G34: Про «Завидово» | H34: A | I34: 10.07.2026
A35: 34 | B35: campaign3 | C35: A@A Дизайн-Артель Алина Горда | D35: gorda.art@mail.ru | F35: г. Москва | G35: Про «Ресторан "Мальдивы"» | H35: B | I35: 10.07.2026
A36: 35 | B36: campaign3 | C36: Андрей и Елена Некрасовы | D36: na.design@mail.ru | E36: 79163961676 | F36: г. Москва | G36: Про «ЖК Небо» | H36: A | I36: 10.07.2026
A37: 36 | B37: campaign3 | C37: 4room studio | D37: hello@4room.studio | F37: г. Москва | G37: Про «Дом в Малаховке» | H37: B | I37: 10.07.2026
A38: 37 | B38: campaign3 | C38: Дмитрий Глушков | D38: ab-glushkov@mail.ru | F38: г. Москва | G38: Про «Кабинет для адвоката» | H38: A | I38: 10.07.2026
A39: 38 | B39: campaign3 | C39: VIVENDI DESIGN | D39: vivendistudio@gmail.com | E39: 79265249075 | F39: г Москва | G39: Про «Апартаменты, 126 кв.м.» | H39: B | I39: 10.07.2026
A40: 39 | B40: campaign3 | C40: Елена Лучина | D40: eeluchina@gmail.com | E40: 79104082287 | F40: г. Москва | G40: Про «ЖК Настоящее» | H40: A | I40: 10.07.2026
...

Sheet Сводка
A1: ПО ПАЧКАМ
A2: Пачка | B2: Контактов | C2: Отправлено | D2: Ответов | E2: Статус пачки
A3: campaign1 | B3: =COUNTIF(Учёт!B:B,"campaign1") -> 9 | C3: =COUNTIFS(Учёт!B:B,"campaign1",Учёт!I:I,"<>") -> 9 | D3: =COUNTIFS(Учёт!B:B,"campaign1",Учёт!K:K,"<>") -> 1 | E3: отправлена 07–08.07
A4: campaign2 | B4: =COUNTIF(Учёт!B:B,"campaign2") -> 15 | C4: =COUNTIFS(Учёт!B:B,"campaign2",Учёт!I:I,"<>") -> 15 | D4: =COUNTIFS(Учёт!B:B,"campaign2",Учёт!K:K,"<>") -> 2 | E4: отправлена 08–09.07
A5: campaign3 | B5: =COUNTIF(Учёт!B:B,"campaign3") -> 15 | C5: =COUNTIFS(Учёт!B:B,"campaign3",Учёт!I:I,"<>") -> 15 | D5: =COUNTIFS(Учёт!B:B,"campaign3",Учёт!K:K,"<>") -> 0 | E5: отправлена 10.07
A6: campaign4 | B6: =COUNTIF(Учёт!B:B,"campaign4") -> 16 | C6: =COUNTIFS(Учёт!B:B,"campaign4",Учёт!I:I,"<>") -> 16 | D6: =COUNTIFS(Учёт!B:B,"campaign4",Учёт!K:K,"<>") -> 0 | E6: отправлена 13.07
A7: campaign5 | B7: =COUNTIF(Учёт!B:B,"campaign5") -> 22 | C7: =COUNTIFS(Учёт!B:B,"campaign5",Учёт!I:I,"<>") -> 0 | D7: =COUNTIFS(Учёт!B:B,"campaign5",Учёт!K:K,"<>") -> 0 | E7: тексты в работе
A8: campaign6 | B8: =COUNTIF(Учёт!B:B,"campaign6") -> 59 | C8: =COUNTIFS(Учёт!B:B,"campaign6",Учёт!I:I,"<>") -> 0 | D8: =COUNTIFS(Учёт!B:B,"campaign6",Учёт!K:K,"<>") -> 0 | E8: тексты в работе
A9: ИТОГО | B9: =SUM(B3:B8) -> 136 | C9: =SUM(C3:C8) -> 55 | D9: =SUM(D3:D8) -> 3
A12: ОТВЕТЫ ПО ТИПАМ
A13: Положительных | B13: =COUNTIF(Учёт!K:K,"положительный") -> 1
A14: Деловых запросов | B14: =COUNTIF(Учёт!K:K,"деловой запрос") -> 1
A15: Отказов | B15: =COUNTIF(Учёт!K:K,"отказ") -> 1
A16: Просили не писать | B16: =COUNTIF(Учёт!K:K,"просил(а) не писать") -> 0
A17: Конверсия в ответ (от отправленных) | B17: =IF(C9=0,"",TEXT(D9/C9,"0.0%")) -> 5.5%
A19: КАК ВЕСТИ
A20: • Даты отправки пачек 1–3 взяты из sent_date ваших CSV, пачка 4 — 13.07.2026.
A21: • Жёлтые ячейки заполняются вручную по ходу кампании.
A22: • Тип ответа и статус — из выпадающих списков, иначе сводка не посчитает.
A23: • Зелёная подсветка имени = уже есть ответ (Липатов, Петрова, Бирюкова).
A24: • Хранить рядом с CSV кампании, вне www.
